<mujoco model="playground">
  <compiler angle="radian" inertiafromgeom="true"/>
  <default>
    <position kp="100.00" ctrlrange="-3.141592 3.141592" forcerange="-150 150"/>
    <joint armature="0.01" damping="1.0" limited="true"/> <geom conaffinity="0" condim="3" contype="1" density="1000" friction=".7 .1 .1" rgba="0.8 0.6 .4 1"/>
  </default>
  <option integrator="RK4" timestep="0.002"/>
  
  <worldbody>
    <light cutoff="100" diffuse="1 1 1" dir="-0 0 -1.3" directional="true" exponent="1" pos="0 0 1.3" specular=".1 .1 .1"/>
    <geom conaffinity="1" condim="3" name="floor" pos="0 0 0" rgba="0.8 0.9 0.8 1" size="40 40 40" type="plane" material="MatPlane"/>
    <camera name="track_com" mode="trackcom" pos="0 -3 -0.25" xyaxes="1 0 0 0 0 1"/>
    
    <body name="torso" pos="0 0 1.33">
      <joint armature="0" axis="1 0 0" damping="0" limited="false" name="rootx" pos="0 0 0" stiffness="0" type="slide"/>
      <joint armature="0" axis="0 0 1" damping="0" limited="false" name="rootz" pos="0 0 0" stiffness="0" type="slide"/>
      <joint armature="0" axis="0 1 0" damping="0" limited="false" name="rooty" pos="0 0 0" stiffness="0" type="hinge"/>
      
      <geom friction="0.9" name="lower_torso_geom" rgba=".7 .3 .6 1" size="0.05 0.12" pos="0 0 -0.12" type="capsule"/>
      
      <body name="thigh" pos="0 0 -0.24">
        <joint axis="0 1 0" name="thigh_joint" range="-1.57 1.57" pos="0 0 0" type="hinge"/>
        <geom friction="0.9" pos="0 0 -0.225" name="thigh_geom" size="0.05 0.225" type="capsule"/>
        <body name="shin" pos="0 0 -0.45">
          <joint axis="0 1 0" name="shin_joint" range="-1.57 1.57" pos="0 0 0" type="hinge"/>
          <geom friction="0.9" rgba=".0 .3 .6 1" pos="0 0 -0.225" name="shin_geom" size="0.05 0.225" type="capsule"/>
        </body>
      </body>
    </body>
  </worldbody>

  <actuator>
    <position joint="thigh_joint" name="pos_thigh"/>
    <position joint="shin_joint" name="pos_shin"/>
  </actuator>
  
  <asset>
    <texture type="skybox" builtin="gradient" rgb1=".4 .5 .6" rgb2="0 0 0" width="100" height="100"/>
    <texture builtin="flat" height="1278" mark="cross" markrgb="1 1 1" name="texgeom" random="0.01" rgb1="0.8 0.6 0.4" rgb2="0.8 0.6 0.4" type="cube" width="127"/>
    <texture builtin="checker" height="100" name="texplane" rgb1="0 0 0" rgb2="0.8 0.8 0.8" type="2d" width="100"/>
    <material name="MatPlane" reflectance="0.5" shininess="1" specular="1" texrepeat="60 60" texture="texplane"/>
    <material name="geom" texture="texgeom" texuniform="true"/>
  </asset>
</mujoco>